Workbook

Sheet REKAP
G1: KARTU INVENTARIS RUANGAN | N1: MODEL INV. 6
A3: Kab/Kota | C3: Kota Banjarmasin
A4: Propinsi | C4: Kalimantan Selatan
A5: Satuan Kerja | C5: Badan Kesatuan Bangsa dan Politik Kota Banjarmasin
A6: Ruangan | C6: REKAP
A8: NO.KODE LOKASI :
A9: No. | B9: Nama Barang | D9: Merk/ | E9: No. Seri | F9: Ukuran | G9: Bahan | H9: Tahun | I9: No/. Kode Barang | J9: Jumlah | K9: Harga | L9: Keadaan Barang | O9: Keterangan
A10: Urut | B10: Jenis Barang | D10: Model | E10: Pabrik | H10: Pembuatan | J10: Barang | K10: Beli/ | L10: Baik | M10: Kurang Baik | N10: Rusak Berat | O10: Keterangan
H11: Atau Pembelian | J11: Register x) | K11: Perolehan | L11: (B) | M11: (KB) | N11: (RB)
A12: 1 | B12: 2 | D12: 3 | E12: 4 | F12: 5 | G12: 6 | H12: 7 | I12: 8 | J12: 9 | K12: 10 | L12: 11 | M12: 12 | N12: 13 | O12: 14
A13: 1 | B13: Lemari Besi | D13: BROTHER / - | G13: Besi | H13: 2008 | I13: 02.06.01.04.001 | J13: 0008 | K13: 1730000 | L13: Baik | O13: Ruang Sekretariat
A14: =A13+1 -> 2 | B14: Lemari Besi | D14: LION / L 33 Swing Door | G14: Besi | H14: 2013 | I14: 02.06.01.04.001 | J14: 0014 | K14: 2820699 | L14: Baik | O14: Ruang Sekretariat
A15: =A14+1 -> 3 | B15: Lemari Besi | D15: Brother / B-203 | G15: Besi | H15: 2014 | I15: 02.06.01.04.001 | J15: 0016 | K15: 3669674 | L15: Baik | O15: Ruang Sekretariat
A16: =A15+1 -> 4 | B16: Filling Besi / Metal | D16: BROTHER / - | G16: Besi | H16: 2006 | I16: 02.06.01.04.004 | J16: 0002 | K16: 1220000 | L16: Baik | M16: Di KIB Kurang Baik | O16: Ruang Sekretariat
A17: =A16+1 -> 5 | B17: Filling Besi / Metal | D17: BROTHER / - | G17: Besi | H17: 2008 | I17: 02.06.01.04.004 | J17: 0003 | K17: 1220000 | L17: Baik | O17: Ruang Sekretariat
A18: =A17+1 -> 6 | B18: Filling Besi / Metal | D18: Secure Line / - | G18: Besi | H18: 2013 | I18: 02.06.01.04.004 | J18: 0007 | K18: 2880334 | L18: Baik | O18: Ruang Sekretariat
A19: =A18+1 -> 7 | B19: Filling Besi / Metal | D19: BROTHER / BS - 102 | G19: Besi | H19: 2014 | I19: 02.06.01.04.004 | J19: 0010 | K19: 3292653 | L19: Baik | O19: Ruang Sekretariat
A20: =A19+1 -> 8 | B20: Filling Besi / Metal | D20: BROTHER / BS - 102 | G20: Besi | H20: 2014 | I20: 02.06.01.04.004 | J20: 0013 | K20: 3292652 | L20: Baik | O20: Ruang Sekretariat
A21: =A20+1 -> 9 | B21: Kursi Putar | D21: USHUTO / Kursi Kerja 6033 | G21: Besi Plastik | H21: 2013 | I21: 02.06.02.01.030 | J21: 0025 | K21: 486971.68 | L21: Baik | O21: Ruang Sekretariat
A22: =A21+1 -> 10 | B22: Kursi Putar | D22: USHUTO / Kursi Kerja 6033 | G22: Besi Plastik | H22: 2013 | I22: 02.06.02.01.030 | J22: 0027 | K22: 486971.68 | L22: Baik | O22: Ruang Sekretariat
A23: =A22+1 -> 11 | B23: Kursi Putar | D23: Indachi/ D 920 | G23: Besi Plastik | H23: 2014 | I23: 02.06.02.01.030 | J23: 0031 | K23: 794180 | L23: Baik | O23: Ruang Kaban
A24: =A23+1 -> 12 | B24: Kursi Putar | D24: Indachi / D 920 | G24: Besi Plastik | H24: 2014 | I24: 02.06.02.01.030 | J24: 0032 | K24: 794180 | L24: Baik | O24: Ruang Sekretariat
A25: =A24+1 -> 13 | B25: Kursi Putar | D25: Indachi / D 920 | G25: Besi Plastik | H25: 2014 | I25: 02.06.02.01.030 | J25: 0033 | K25: 794180 | L25: Baik | O25: Ruang Sekretariat
A26: =A25+1 -> 14 | B26: Kursi Putar | D26: Indachi/ D 920 | G26: Besi Plastik | H26: 2014 | I26: 02.06.02.01.030 | J26: 0038 | K26: 794180 | L26: Baik | O26: Ruang Kaban
A27: =A26+1 -> 15 | B27: Kursi Putar | D27: Indachi / D 920 | G27: Besi Plastik | H27: 2014 | I27: 02.06.02.01.030 | J27: 0041 | K27: 794180 | L27: Baik | O27: Ruang Sekretariat
A28: =A27+1 -> 16 | B28: Kursi Rapat | D28: Chitose / Warna Biru | G28: Besi | H28: 2009 | I28: 02.06.02.01.027 | J28: 0002 | K28: 350000 | L28: Baik | O28: Ruang Sekretariat
... A30: =A29+1 -> 18 | B30: Kursi Rapat | D30: Chitose / Warna Biru | G30: Besi | H30: 2009 | I30: 02.06.02.01.027 | J30: 0005 | K30: 350000 | L30: Baik | O30: Ruang Sekretariat
A31: =A30+1 -> 19 | B31: Kursi Lipat | D31: MATRIX / - | H31: 2018 | I31: 02.06.02.01.034 | J31: 0007 | K31: 333232 | L31: Baik | O31: Ruang Sekretaris
A32: =A31+1 -> 20 | B32: Kursi Lipat | D32: MATRIX / - | H32: 2018 | I32: 02.06.02.01.034 | J32: 0008 | K32: 333232 | L32: Baik | O32: Ruang Sekretaris
A33: =A32+1 -> 21 | B33: Sofa | D33: 3.2.1. In Frame IF 007Hitam/CT Royal 0198/Espresso 0197 | G33: Kulit Hitam | H33: 2013 | I33: 02.06.02.01.049 | J33: 0001 | K33: 9384350.04 | L33: Baik | O33: Ruang Sekretaris
A34: =A33+1 -> 22 | B34: Sofa | D34: LEXUS / 321 | H34: 2020 | I34: 02.06.02.01.049 | J34: 0002 | K34: 12524430 | L34: Baik | O34: Ruang Kaban
A35: =A34+1 -> 23 | B35: Lemari Es | D35: Kulkas SHARP/ SJ19BHTB | G35: Besi | H35: 2012 | I35: 02.06.02.04.001 | J35: 0001 | K35: 1975000 | L35: Baik | O35: Ruang Kaban
A36: =A35+1 -> 24 | B36: AC Unit | D36: Daikin/ FTV25BXV | G36: 1 PK | H36: 2019 | I36: 02.06.02.04.003 | J36: 0014 | K36: 5033356 | L36: Baik | O36: Ruang Kaban
A37: =A36+1 -> 25 | B37: AC Unit | D37: Daikin/FTV25CXV | H37: 2020 | I37: 02.06.02.04.003 | J37: 0015 | K37: 8165750 | L37: Baik | O37: Ruang Sekretaris
A38: =A37+1 -> 26 | B38: Televisi | D38: THOSIBA/ 47L2400VJ | G38: Besi Plastik | H38: 2014 | I38: 02.06.02.06.003 | J38: 0005 | K38: 10223684 | L38: Baik | O38: Ruang Kaban
A39: =A38+1 -> 27 | B39: Televisi | D39: Samsung./ 43n5001 | H39: 2020 | I39: 02.06.02.06.003 | J39: 0006 | K39: =16532240/3 -> 5510746.7 | L39: Baik | O39: Ruang Kaban
A40: =A39+1 -> 28 | B40: Camera Video | D40: CCTV/UVR SPC 8 CH / KAMERA SPC 2 MP | G40: Besi Plastik | H40: 2019 | I40: 02.06.02.06.021 | J40: 0002 | K40: 4620620 | L40: Baik | O40: Ruang Kaban
A41: =A40+1 -> 29 | B41: PC Unit | D41: Intel - Casing DE Case-LG Pentium ® G 2020 Asrock HG1-LG LED16 | G41: Besi Plastik | H41: 2013 16 Inci | I41: 02.06.03.02.001 | J41: 0012 | K41: 3922641.5 | L41: Baik | O41: Ruang Sekretariat
A42: =A41+1 -> 30 | B42: PC Unit | D42: Lenovo / C260 | G42: Besi Plastik | H42: 2015 | I42: 02.06.03.02.001 | J42: 0013 | K42: 6026316 | L42: Baik | O42: Ruang Sekretariat
A43: =A42+1 -> 31 | B43: PC Unit | D43: Lenovo / 330 -20 GM AIO | G43: Besi Plastik | H43: 2019 | I43: 02.06.03.02.001 | J43: 0020 | K43: 5327418 | L43: Baik | O43: Ruang Sekretariat
...

Sheet RUANG KABAN
H1: KARTU INVENTARIS RUANGAN | O1: MODEL INV. 6
B2: Kab/Kota | D2: Kota Banjarmasin
B3: Propinsi | D3: Kalimantan Selatan
B4: Satuan Kerja | D4: Badan Kesatuan Bangsa dan Politik Kota Banjarmasin
B5: Ruangan | D5: Kepala Badan
B7: NO.KODE LOKASI :
B8: No. | C8: Nama Barang | E8: Merk/ | F8: No. Seri | G8: Ukuran | H8: Bahan | I8: Tahun | K8: Jumlah | L8: Harga | M8: Keadaan Barang | P8: Keterangan
B9: Urut | C9: Jenis Barang | E9: Model | F9: Pabrik | I9: Pembuatan | J9: No/. Kode Barang | K9: Barang | L9: Beli/ | M9: Baik | N9: Kurang Baik | O9: Rusak Berat | P9: Mutasi dll
I10: Atau Pembelian | K10: Register x) | L10: Perolehan | M10: (B) | N10: (KB) | O10: (RB)
B11: 1 | C11: 2 | E11: 3 | F11: 4 | G11: 5 | H11: 6 | I11: 7 | J11: 8 | K11: 9 | L11: 10 | M11: 11 | N11: 12 | O11: 13 | P11: 14
B12: 1 | C12: Papan Tulis | E12: Papan Data Nominatif / Buatan Lokal | H12: Papan | I12: 2010 | J12: 02.06.01.05.008 | K12: 0001 | L12: 1350000 | M12: Baik
B13: =B12+1 -> 2 | C13: Kursi Putar | E13: Indachi/ D 920 | H13: Besi Plastik | I13: 2014 | J13: 02.06.02.01.030 | K13: 0031 | L13: 794180 | M13: Baik
B14: =B13+1 -> 3 | C14: Kursi Putar | E14: Indachi/ D 920 | H14: Besi Plastik | I14: 2014 | J14: 02.06.02.01.030 | K14: 0038 | L14: 794180 | M14: Baik
B15: =B14+1 -> 4 | C15: Sofa | E15: LEXUS / 321 | I15: 2020 | J15: 02.06.02.01.049 | K15: 0002 | L15: 12524430 | M15: Baik
B16: =B15+1 -> 5 | C16: Lemari Es | E16: Kulkas SHARP/ SJ19BHTB | H16: Besi | I16: 2012 | J16: 02.06.02.04.001 | K16: 0001 | L16: 1975000 | M16: Baik
B17: =B16+1 -> 6 | C17: AC Unit | E17: Daikin/ FTV25BXV | H17: 1 PK | I17: 2019 | J17: 02.06.02.04.003 | K17: 0014 | L17: 5033356 | M17: Baik
B18: =B17+1 -> 7 | C18: Televisi | E18: THOSIBA/ 47L2400VJ | H18: Besi Plastik | I18: 2014 | J18: 02.06.02.06.003 | K18: 0005 | L18: 10223684 | M18: Baik
B19: =B18+1 -> 8 | C19: Televisi | E19: Samsung./ 43n5001 | I19: 2020 | J19: 02.06.02.06.003 | K19: 0006 | L19: =16532240/3 -> 5510746.7 | M19: Baik
B20: =B19+1 -> 9 | C20: Camera Video | E20: CCTV/UVR SPC 8 CH / KAMERA SPC 2 MP | H20: Besi Plastik | I20: 2019 | J20: 02.06.02.06.021 | K20: 0002 | L20: 4620620 | M20: Baik
B21: =B20+1 -> 10 | C21: Meja Kerja Pejabat Eselon II | E21: Zetta MT 301/Esselon II | H21: Kayu Partikel | I21: 2016 | J21: 02.06.04.01.004 | K21: 0002 | L21: 2333333 | M21: Baik
D24: Mengetahui : | M24: Banjarmasin, Desember 2025
D25: Kepala Bakesbangpol Kota Banjarmasin, | M25: Pengurus Barang,
D29: Dr. H. LUKMAN FADLUN, SH, MH | M29: TRISNAWATI M ULYO HAPSARI, SE
D30: Pembina Utama Muda | M30: NIP. 19721124 200604 2 005
D31: NIP. 19691013 200003 1 004

Sheet RUANG SEKRETARIS
G1: KARTU INVENTARIS RUANGAN | N1: MODEL INV. 6
A3: Kab/Kota | C3: Kota Banjarmasin
A4: Propinsi | C4: Kalimantan Selatan
A5: Satuan Kerja | C5: Badan Kesatuan Bangsa dan Politik Kota Banjarmasin
A6: Ruangan | C6: Sekretaris
A8: NO.KODE LOKASI :
A9: No. | B9: Nama Barang | D9: Merk/ | E9: No. Seri | F9: Ukuran | G9: Bahan | H9: Tahun | J9: Jumlah | K9: Harga | L9: Keadaan Barang | O9: Keterangan
A10: Urut | B10: Jenis Barang | D10: Model | E10: Pabrik | H10: Pembuatan | I10: No/. Kode Barang | J10: Barang | K10: Beli/ | L10: Baik | M10: Kurang Baik | N10: Rusak Berat | O10: Mutasi dll
H11: Atau Pembelian | J11: Register x) | K11: Perolehan | L11: (B) | M11: (KB) | N11: (RB)
A12: 1 | B12: 2 | D12: 3 | E12: 4 | F12: 5 | G12: 6 | H12: 7 | I12: 8 | J12: 9 | K12: 10 | L12: 11 | M12: 12 | N12: 13 | O12: 14
A13: 1 | B13: Kursi Lipat | D13: MATRIX / - | H13: 2018 | I13: 02.06.02.01.034 | J13: 0007 | K13: 333232 | L13: Baik
A14: =A13+1 -> 2 | B14: Kursi Lipat | D14: MATRIX / - | H14: 2018 | I14: 02.06.02.01.034 | J14: 0008 | K14: 333232 | L14: Baik
A15: =A14+1 -> 3 | B15: Sofa | D15: 3.2.1. In Frame IF 007Hitam/CT Royal 0198/Espresso 0197 | G15: Kulit Hitam | H15: 2013 | I15: 02.06.02.01.049 | J15: 0001 | K15: 9384350 | L15: Baik
A16: =A15+1 -> 4 | B16: AC Unit | D16: Daikin/FTV25CXV | H16: 2020 | I16: 02.06.02.04.003 | J16: 0015 | K16: 8165750 | L16: Baik
A17: =A16+1 -> 5 | B17: Printer | D17: Epson ECO Tank L3110N /- | G17: Campuran | H17: 2020 | I17: 02.06.03.05.003 | J17: 0033 | K17: 2783950 | L17: Baik
A18: =A17+1 -> 6 | B18: Meja Kerja Pejabat Eselon II | D18: Zetta MT 301 / Esselon II | G18: Kayu Partikel | H18: 2014 | I18: 02.06.04.01.004 | J18: 0001 | K18: 5780423 | L18: Baik
A19: =A18+1 -> 7 | B19: Kursi Kerja Pejabat Eselon III | D19: Tiger T904 Esselon III | G19: Besi Plastik | H19: 2011 | I19: 02.06.04.03.005 | J19: 0006 | K19: 1485000 | L19: Baik
A20: =A19+1 -> 8 | B20: Lemari dan Arsip Pejabat Lain-lain | D20: Informa MC Glass Door/Lemari Buku | G20: Kayu Partikel | H20: 2016 | I20: 02.06.04.07.009 | J20: 0001 | K20: 2739131 | L20: Baik
C23: Mengetahui : | L23: Banjarmasin, Desember 2025
C24: Kepala Bakesbangpol Kota Banjarmasin, | L24: Pengurus Barang,
C28: Dr. H. LUKMAN FADLUN, SH, MH | L28: TRISNAWATI M ULYO HAPSARI, SE
C29: Pembina Utama Muda | L29: ='RUANG KABAN'!M30 -> NIP. 19721124 200604 2 005
C30: NIP. 19691013 200003 1 004

Sheet RUANG SEKRETARIAT
G1: KARTU INVENTARIS RUANGAN | N1: MODEL INV. 6
A3: Kab/Kota | C3: Kota Banjarmasin
A4: Propinsi | C4: Kalimantan Selatan
A5: Satuan Kerja | C5: Badan Kesatuan Bangsa dan Politik Kota Banjarmasin
A6: Ruangan | C6: SEKRETARIAT
A8: NO.KODE LOKASI :
A9: No. | B9: Nama Barang | D9: Merk/ | E9: No. Seri | F9: Ukuran | G9: Bahan | H9: Tahun | J9: Jumlah | K9: Harga | L9: Keadaan Barang | O9: Keterangan
A10: Urut | B10: Jenis Barang | D10: Model | E10: Pabrik | H10: Pembuatan | I10: No. Kode Barang | J10: Barang | K10: Beli/ | L10: Baik | M10: Kurang Baik | N10: Rusak Berat | O10: Mutasi dll
H11: Atau Pembelian | J11: Register x) | K11: Perolehan | L11: (B) | M11: (KB) | N11: (RB)
A12: 1 | B12: 2 | D12: 3 | E12: 4 | F12: 5 | G12: 6 | H12: 7 | I12: 8 | J12: 9 | K12: 10 | L12: 11 | M12: 12 | N12: 13 | O12: 14
A13: 1 | B13: Lemari Besi | D13: BROTHER / - | G13: Besi | H13: 2008 | I13: 02.06.01.04.001 | J13: 0008 | K13: 1730000 | L13: Baik
A14: =A13+1 -> 2 | B14: Lemari Besi | D14: LION / L 33 Swing Door | G14: Besi | H14: 2013 | I14: 02.06.01.04.001 | J14: 0014 | K14: 2820699 | L14: Baik
A15: =A14+1 -> 3 | B15: Lemari Besi | D15: Brother / B-203 | G15: Besi | H15: 2014 | I15: 02.06.01.04.001 | J15: 0016 | K15: 3669674 | L15: Baik
A16: =A15+1 -> 4 | B16: Filling Besi / Metal | D16: BROTHER / - | G16: Besi | H16: 2006 | I16: 02.06.01.04.004 | J16: 0002 | K16: 1220000 | L16: Baik | M16: Di KIB Kurang Baik
A17: =A16+1 -> 5 | B17: Filling Besi / Metal | D17: BROTHER / - | G17: Besi | H17: 2008 | I17: 02.06.01.04.004 | J17: 0003 | K17: 1220000 | L17: Baik
A18: =A17+1 -> 6 | B18: Filling Besi / Metal | D18: Secure Line / - | G18: Besi | H18: 2013 | I18: 02.06.01.04.004 | J18: 0007 | K18: 2880334 | L18: Baik
A19: =A18+1 -> 7 | B19: Filling Besi / Metal | D19: BROTHER / BS - 102 | G19: Besi | H19: 2014 | I19: 02.06.01.04.004 | J19: 0010 | K19: 3292653 | L19: Baik
A20: =A19+1 -> 8 | B20: Filling Besi / Metal | D20: BROTHER / BS - 102 | G20: Besi | H20: 2014 | I20: 02.06.01.04.004 | J20: 0013 | K20: 3292652 | L20: Baik
A21: =A20+1 -> 9 | B21: Kursi Putar | D21: USHUTO / Kursi Kerja 6033 | G21: Besi Plastik | H21: 2013 | I21: 02.06.02.01.030 | J21: 0025 | K21: 486971.68 | L21: Baik
A22: =A21+1 -> 10 | B22: Kursi Putar | D22: USHUTO / Kursi Kerja 6033 | G22: Besi Plastik | H22: 2013 | I22: 02.06.02.01.030 | J22: 0027 | K22: 486971.68 | L22: Baik
A23: =A22+1 -> 11 | B23: Kursi Putar | D23: Indachi / D 920 | G23: Besi Plastik | H23: 2014 | I23: 02.06.02.01.030 | J23: 0032 | K23: 794180 | L23: Baik
A24: =A23+1 -> 12 | B24: Kursi Putar | D24: Indachi / D 920 | G24: Besi Plastik | H24: 2014 | I24: 02.06.02.01.030 | J24: 0033 | K24: 794180 | L24: Baik
A25: =A24+1 -> 13 | B25: Kursi Putar | D25: Indachi / D 920 | G25: Besi Plastik | H25: 2014 | I25: 02.06.02.01.030 | J25: 0041 | K25: 794180 | L25: Baik
A26: =A25+1 -> 14 | B26: Kursi Rapat | D26: Chitose / Warna Biru | G26: Besi | H26: 2009 | I26: 02.06.02.01.027 | J26: 0002 | K26: 350000 | L26: Baik
A27: =A26+1 -> 15 | B27: Kursi Rapat | D27: Chitose / Warna Biru | G27: Besi | H27: 2009 | I27: 02.06.02.01.027 | J27: 0004 | K27: 350000 | L27: Baik
A28: =A27+1 -> 16 | B28: Kursi Rapat | D28: Chitose / Warna Biru | G28: Besi | H28: 2009 | I28: 02.06.02.01.027 | J28: 0005 | K28: 350000 | L28: Baik
A29: =A28+1 -> 17 | B29: PC Unit | D29: Intel - Casing DE Case-LG Pentium ® G 2020 Asrock HG1-LG LED16 | G29: Besi Plastik | H29: 2013 16 Inci | I29: 02.06.03.02.001 | J29: 0017 | K29: 3922641.5 | L29: Baik
A30: =A29+1 -> 18 | B30: PC Unit | D30: Lenovo / C260 | G30: Besi Plastik | H30: 2015 | I30: 02.06.03.02.001 | J30: 0013 | K30: 6026316 | L30: Baik
A38: No. | B38: Nama Barang | D38: Merk/ | E38: No. Seri | F38: Ukuran | G38: Bahan | H38: Tahun | J38: Jumlah | K38: Harga | L38: Keadaan Barang | O38: Keterangan
A39: Urut | B39: Jenis Barang | D39: Model | E39: Pabrik | H39: Pembuatan | I39: No. Kode Barang | J39: Barang | K39: Beli/ | L39: Baik | M39: Kurang Baik | N39: Rusak Berat | O39: Mutasi dll
H40: Atau Pembelian | J40: Register x) | K40: Perolehan | L40: (B) | M40: (KB) | N40: (RB)
A41: 1 | B41: 2 | D41: 3 | E41: 4 | F41: 5 | G41: 6 | H41: 7 | I41: 8 | J41: 9 | K41: 10 | L41: 11 | M41: 12 | N41: 13 | O41: 14
A42: =A30+1 -> 19 | B42: PC Unit | D42: Lenovo / 330 -201 GM AIO | G42: Besi Plastik | H42: 2019 | I42: 02.06.03.02.001 | J42: 0018 | K42: 5327418 | L42: Baik | O42: Ibu TAty
A43: =A42+1 -> 20 | B43: PC Unit | D43: Lenovo / 330 -201 GM AIO | G43: Besi Plastik | H43: 2019 | I43: 02.06.03.02.001 | J43: 0019 | K43: 5327418 | L43: Baik | O43: Indra H
A44: =A43+1 -> 21 | B44: PC Unit | D44: Lenovo / 330 -201 GM AIO | G44: Besi Plastik | H44: 2019 | I44: 02.06.03.02.001 | J44: 0020 | K44: 5327418 | L44: Baik | O44: Rosy
A45: =A44+1 -> 22 | B45: PC Unit | D45: LENOVO V130 / - | G45: Campuran | H45: 2020 | I45: 02.06.03.02.001 | J45: 0021 | K45: 5567960 | L45: Baik | O45: Indra A
A46: =A45+1 -> 23 | B46: Printer | D46: EPSON / L 360 | G46: Besi Plastik | H46: 2016 | I46: 02.06.03.05.003 | J46: 0021 | K46: 3142612 | L46: Baik | O46: Ibu Taty
A47: =A46+1 -> 24 | B47: Printer | D47: EPSON / L 120 | G47: Besi Plastik | H47: 2016 | I47: 02.06.03.05.003 | J47: 0024 | K47: 2000000 | L47: Baik | O47: Yanti
A48: =A47+1 -> 25 | B48: Printer | D48: EPSON / L 120 | G48: Besi Plastik | H48: 2016 | I48: 02.06.03.05.003 | J48: 0025 | K48: 2000000 | L48: Baik | O48: Roisy
A49: =A48+1 -> 26 | B49: Printer | D49: EPSON / L 3110 | G49: Besi | H49: 2019 | I49: 02.06.03.05.003 | J49: 0030 | K49: 2512933 | L49: Baik | O49: Indra A
...

Sheet RUANG KASUBBAG KEUANGAN
G1: KARTU INVENTARIS RUANGAN | N1: MODEL INV. 6
A3: Kab/Kota | C3: Kota Banjarmasin
A4: Propinsi | C4: Kalimantan Selatan
A5: Satuan Kerja | C5: Badan Kesatuan Bangsa dan Politik Kota Banjarmasin
A6: Ruangan | C6: Kasubbag Keuangan
A8: NO.KODE LOKASI :
A9: No. | B9: Nama Barang | D9: Merk/ | E9: No. Seri | F9: Ukuran | G9: Bahan | H9: Tahun | J9: Jumlah | K9: Harga | L9: Keadaan Barang | O9: Keterangan
A10: Urut | B10: Jenis Barang | D10: Model | E10: Pabrik | H10: Pembuatan | I10: No. Kode Barang | J10: Barang | K10: Beli/ | L10: Baik | M10: Kurang Baik | N10: Rusak Berat | O10: Mutasi dll
H11: Atau Pembelian | J11: Register x) | K11: Perolehan | L11: (B) | M11: (KB) | N11: (RB)
A12: 1 | B12: 2 | D12: 3 | E12: 4 | F12: 5 | G12: 6 | H12: 7 | I12: 8 | J12: 9 | K12: 10 | L12: 11 | M12: 12 | N12: 13 | O12: 14
A13: 1 | B13: Lemari Besi | D13: Lion / Brangkas | G13: Besi | H13: 2000 | I13: 02/06.01.04.001 | J13: 0007 | K13: 5190000 | L13: Baik
A14: =A13+1 -> 2 | B14: Lemari Kaca | D14: Brother / Besi Kaca | G14: Besi Kaca | H14: 2006 | I14: 02.06.01.04.012 | J14: 0001 | K14: 1820000 | L14: Baik
A15: =A14+1 -> 3 | B15: Lemari Kayu | D15: Brother / 4 Rak | G15: Kayu Partikel | H15: 2006 | I15: 02.06.01.04.014 | J15: 0001 | K15: 250000 | L15: Baik
A16: =A15+1 -> 4 | B16: Kursi Lipat | D16: MATRIX / - | H16: 2018 | I16: 02.06.02.01.034 | J16: 0002 | K16: 333232 | L16: Baik
A17: =A16+1 -> 5 | B17: AC Unit | D17: DAIKIN/FTNE25JEV14 | I17: 02.05.02.04.002
A18: =A17+1 -> 6 | B18: Dispenser | D18: Toshiba / RWFW1830 | H18: 2020 | I18: 02.06.02.06.039 | J18: 0002 | K18: =8917390/2 -> 4458695 | L18: Baik
A19: =A18+1 -> 7 | B19: Kursi Kerja Pejabat Eselon IV | D19: Indachi D 821 CR/Kursi Kerja Staf | G19: Kayu Partikel | H19: 2016 | I19: 02.06.04.03.006 | J19: 0008 | K19: 2181159 | L19: Baik
A20: =A19+1 -> 8 | B20: Meja Kerja Pejabat Eselon IV | D20: Pro Design/Meja Kerja VPM 120 | G20: Kayu Partikel | H20: 2010 | I20: 02.06.04.01.006 | J20: 0021 | K20: 593750 | L20: Baik
C23: Mengetahui : | L23: Banjarmasin, Desember 2025
C25: Kepala Bakesbangpol Kota Banjarmasin, | L25: Pengurus Barang,
C29: Dr. H. LUKMAN FADLUN, SH, MH | L29: TRISNAWATI M ULYO HAPSARI, SE
C30: Pembina Utama Muda | L30: ='RUANG KABAN'!M30 -> NIP. 19721124 200604 2 005
C31: NIP. 19691013 200003 1 004

Sheet RUANG KASUBBAG UMPEG
G1: KARTU INVENTARIS RUANGAN | N1: MODEL INV. 6
A3: Kab/Kota | C3: Kota Banjarmasin
A4: Propinsi | C4: Kalimantan Selatan
A5: Satuan Kerja | C5: Badan Kesatuan Bangsa dan Politik Kota Banjarmasin
A6: Ruangan | C6: Kasubbag Umum dan Kepegawaian
A8: NO.KODE LOKASI :
A9: No. | B9: Nama Barang | D9: Merk/ | E9: No. Seri | F9: Ukuran | G9: Bahan | H9: Tahun | J9: Jumlah | K9: Harga | L9: Keadaan Barang | O9: Keterangan
A10: Urut | B10: Jenis Barang | D10: Model | E10: Pabrik | H10: Pembuatan | I10: No. Kode Barang | J10: Barang | K10: Beli/ | L10: Baik | M10: Kurang Baik | N10: Rusak Berat | O10: Mutasi dll
H11: Atau Pembelian | J11: Register x) | K11: Perolehan | L11: (B) | M11: (KB) | N11: (RB)
A12: 1 | B12: 2 | D12: 3 | E12: 4 | F12: 5 | G12: 6 | H12: 7 | I12: 8 | J12: 9 | K12: 10 | L12: 11 | M12: 12 | N12: 13 | O12: 14
A13: 1 | B13: Lemari Besi | D13: KRISBROW / KW 17 - 195 | G13: Besi | H13: 2012 | I13: 02.06.01.04.001 | J13: 0011 | K13: 3400000 | L13: Baik
A14: =A13+1 -> 2 | B14: Filling Besi / Metal | D14: Secure Line /- | G14: Besi | H14: 2013 | I14: 02.06.01.04.004 | J14: 0009 | K14: 2880334 | L14: Baik
A15: =A14+1 -> 3 | B15: Filling Besi / Metal | D15: BROTHER / BS-102 | G15: Besi | H15: 2014 | I15: 02.06.01.04.004 | J15: 0011 | K15: 3292653 | L15: Baik
A16: =A15+1 -> 4 | B16: Lemari Kayu | D16: Big Panel / 4 Rak | G16: Kayu Partikel | H16: 2010 | I16: 02.06.01.04.014 | J16: 0002 | K16: 396000 | L16: Baik | O16: sudah dipindahkan
A17: =A16+1 -> 5 | B17: Kursi Putar | D17: Indachi D 920 | G17: Besi Plastik | H17: 2014 | I17: 02.06.02.01.030 | J17: 0045 | K17: 1588358 | L17: Baik
A18: =A17+1 -> 6 | B18: Kursi Lipat | D18: MATRIX / - | H18: 2018 | I18: 02.06.02.01.034 | J18: 0003 | K18: 333232 | L18: Baik
A19: =A18+1 -> 7 | B19: AC Unit | D19: Daikin/ FTNE25MV | H19: 2018 1 PK | I19: 02.06.02.04.003 | J19: 0013 | K19: 5009175 | L19: Baik
A20: =A19+1 -> 8 | B20: Printer | D20: EPSON /L360 | H20: 2018 | I20: 02.06.03.05.003 | J20: 0029 | K20: 2428691 | L20: Baik
A21: =A20+1 -> 9 | B21: Meja Kerja Pejabat Eselon IV | D21: ZETTA / MT201 | H21: 2019 | I21: 02.06.04.01.006 | J21: 0040 | K21: 2245000 | L21: Baik
C24: Mengetahui : | L24: Banjarmasin, Desember 2025
C25: Kepala Bakesbangpol Kota Banjarmasin, | L25: Pengurus Barang,
C29: Dr. H. LUKMAN FADLUN, SH, MH | L29: TRISNAWATI M ULYO HAPSARI, SE
C30: Pembina Utama Muda | L30: ='RUANG KABAN'!M30 -> NIP. 19721124 200604 2 005
C31: NIP. 19691013 200003 1 004

Sheet RUANG KASUBBAG SUNRAM
G1: KARTU INVENTARIS RUANGAN | N1: MODEL INV. 6
A3: Kab/Kota | C3: Kota Banjarmasin
A4: Propinsi | C4: Kalimantan Selatan
A5: Satuan Kerja | C5: Badan Kesatuan Bangsa dan Politik Kota Banjarmasin
A6: Ruangan | C6: Kasubbag Penyusunan Program
A8: NO.KODE LOKASI :
A9: No. | B9: Nama Barang | D9: Merk/ | E9: No. Seri | F9: Ukuran | G9: Bahan | H9: Tahun | J9: Jumlah | K9: Harga | L9: Keadaan Barang | O9: Keterangan
A10: Urut | B10: Jenis Barang | D10: Model | E10: Pabrik | H10: Pembuatan | I10: No. Kode Barang | J10: Barang | K10: Beli/ | L10: Baik | M10: Kurang Baik | N10: Rusak Berat | O10: Mutasi dll
H11: Atau Pembelian | J11: Register x) | K11: Perolehan | L11: (B) | M11: (KB) | N11: (RB)
A12: 1 | B12: 2 | D12: 3 | E12: 4 | F12: 5 | G12: 6 | H12: 7 | I12: 8 | J12: 9 | K12: 10 | L12: 11 | M12: 12 | N12: 13 | O12: 14
A13: 1 | B13: Filling Besi / Metal | D13: Secure Line /- | G13: Besi | H13: 2013 | I13: 02.06.01.04.004 | J13: 0008 | K13: 2880334 | L13: Baik
A14: =A13+1 -> 2 | B14: Lemari Kaca | D14: Brother / Besi Kaca 8304 | G14: Besi Kaca | H14: 2014 | I14: 02.06.01.04.012 | J14: 0002 | K14: 3050000 | L14: Baik
A15: =A14+1 -> 3 | B15: Kursi Lipat | D15: MATRIX/- | H15: 2018 | I15: 02.06.02.01.034 | J15: 0001 | K15: 333232 | L15: Baik
A16: =A15+1 -> 4 | B16: AC Unit | D16: Samsung/AR09 HCFSTWKNSE | G16: Besi Plastik 1 PK | H16: 2014 | I16: 02.06.02.04.003 | J16: 0008 | K16: 4916358 | L16: Baik
A17: =A16+1 -> 5 | B17: Meja Kerja Pejabat Eselon III | D17: ZETTA/MT-201 / Esselon III | G17: Kayu Partikel | H17: 2017 | I17: 02.06.04.01.005 | J17: 0006 | K17: 2284351 | L17: Baik
A18: =A17+1 -> 6 | B18: Kursi Kerja Pejabat Eselon III | D18: INDACHI / 741 CR | G18: Besi Plastik | H18: 2011 | I18: 02.06.04.03.005 | J18: 0007 | K18: 1485000 | L18: Baik
C21: Mengetahui : | L21: Banjarmasin, Desember 2025
C23: Kepala Bakesbangpol Kota Banjarmasin, | L23: Pengurus Barang,
C27: Dr. H. LUKMAN FADLUN, SH, MH | L27: TRISNAWATI M ULYO HAPSARI, SE
C28: Pembina Utama Muda | L28: ='RUANG SEKRETARIS'!L29 -> NIP. 19721124 200604 2 005
C29: NIP. 19691013 200003 1 004

Sheet RUANG SELASAR
G1: KARTU INVENTARIS RUANGAN | N1: MODEL INV. 6
A3: Kab/Kota | C3: Kota Banjarmasin
A4: Propinsi | C4: Kalimantan Selatan
A5: Satuan Kerja | C5: Badan Kesatuan Bangsa dan Politik Kota Banjarmasin
A6: Ruangan | C6: SELASAR
A8: NO.KODE LOKASI :
A9: No. | B9: Nama Barang | D9: Merk/ | E9: No. Seri | F9: Ukuran | G9: Bahan | H9: Tahun | J9: Jumlah | K9: Harga | L9: Keadaan Barang | O9: Keterangan
A10: Urut | B10: Jenis Barang | D10: Model | E10: Pabrik | H10: Pembuatan | I10: No. Kode Barang | J10: Barang | K10: Beli/ | L10: Baik | M10: Kurang Baik | N10: Rusak Berat | O10: Mutasi dll
H11: Atau Pembelian | J11: Register x) | K11: Perolehan | L11: (B) | M11: (KB) | N11: (RB)
A12: 1 | B12: 2 | D12: 3 | E12: 4 | F12: 5 | G12: 6 | H12: 7 | I12: 8 | J12: 9 | K12: 10 | L12: 11 | M12: 12 | N12: 13 | O12: 14
A13: 1 | B13: Lemari Besi | D13: Platinum / Alba - | G13: Besi | H13: 1992 | I13: 02.06.01.04.001 | J13: 0001 | K13: 1225000 | M13: Kurang Baik
A14: =A13+1 -> 2 | B14: Lemari Besi | D14: Brother / - | G14: Besi | H14: 1992 | I14: 02.06.01.04.001 | J14: 0002 | K14: 1225000 | M14: Kurang Baik
A15: =A14+1 -> 3 | B15: Lemari Besi | D15: Brother / - | G15: Besi | H15: 1994 | I15: 02.06.01.04.001 | J15: 0004 | K15: 1225000 | M15: Kurang Baik
A16: =A15+1 -> 4 | B16: Lemari Besi | D16: Lion / - | G16: Besi | H16: 2009 | I16: 02.06.01.04.001 | J16: 0010 | K16: 2500000 | L16: Baik
A17: =A16+1 -> 5 | B17: Lemari Besi | D17: Brother / B 203 | G17: Besi | H17: 2014 | I17: 02.06.01.04.001 | J17: 0015 | K17: 3669674 | L17: Baik
A18: =A17+1 -> 6 | B18: Lemari Kayu | D18: Buatan Lokal / Kayu Kaca | G18: Kayu Kaca | H18: 2010 | I18: 02.06.01.04.014 | J18: 0004 | K18: 900000 | L18: Baik
A19: =A18+1 -> 7 | B19: Lemari Kayu | D19: SAGA RB 2800/ Lemari Buku | G19: Kayu Partikel | H19: 2011 | I19: 02.06.01.04.014 | J19: 0006 | K19: 892500 | L19: Baik
A20: =A19+1 -> 8 | B20: Mesin Absensi | D20: MBIO / MB 007c | G20: Besi Plastik | H20: 2019 | I20: 02.06.01.05.017 | J20: 0002 | K20: 4630687 | L20: Baik
A21: =A20+1 -> 9 | B21: PC Unit | D21: Intel - Casing DE Case-LG / Pentium ® G 2020Asrock HGI-LG LED 16 | G21: Besi Plastik | H21: 2013 | I21: 02.06.03.02.001 | J21: 0011 | K21: 3922641.5 | L21: Baik
A22: =A21+1 -> 10 | B22: Meja Kerja Pejabat Eselon IV | D22: SAGA / Meja Kerja | G22: Kayu Partikel | H22: 2009 | I22: 02.06.04.01.006 | J22: 0016 | K22: 400000 | L22: Baik
A23: =A22+1 -> 11 | B23: Kursi Kerja Pejabat Eselon IV | D23: BROTHER BG 510 AN / Kursi Kerja | G23: Kayu Partikel | H23: 2017 | I23: 02.06.04.03.006 | J23: 0010 | K23: 1066031 | L23: Baik
C25: Mengetahui : | L25: Banjarmasin, Desember 2025
C27: Kepala Bakesbangpol Kota Banjarmasin, | L27: Pengurus Barang,
C31: Dr. H. LUKMAN FADLUN, SH, MH | L31: TRISNAWATI M ULYO HAPSARI, SE
C32: Pembina Utama Muda | L32: NIP. 19721124 200604 2 005
C33: NIP. 19691013 200003 1 004

Sheet RUANG RAPAT
G1: KARTU INVENTARIS RUANGAN | N1: MODEL INV. 6
A2: Kab/Kota | C2: Kota Banjarmasin
A3: Propinsi | C3: Kalimantan Selatan
A4: Satuan Kerja | C4: Badan Kesatuan Bangsa dan Politik Kota Banjarmasin
A5: Ruangan | C5: RAPAT
A7: NO.KODE LOKASI :
A8: No. | B8: Nama Barang | D8: Merk/ | E8: No. Seri | F8: Ukuran | G8: Bahan | H8: Tahun | J8: Jumlah | K8: Harga | L8: Keadaan Barang | O8: Keterangan
A9: Urut | B9: Jenis Barang | D9: Model | E9: Pabrik | H9: Pembuatan | I9: No. Kode Barang | J9: Barang | K9: Beli/ | L9: Baik | M9: Kurang Baik | N9: Rusak Berat | O9: Mutasi dll
H10: Atau Pembelian | J10: Register x) | K10: Perolehan | L10: (B) | M10: (KB) | N10: (RB)
A11: 1 | B11: 2 | D11: 3 | E11: 4 | F11: 5 | G11: 6 | H11: 7 | I11: 8 | J11: 9 | K11: 10 | L11: 11 | M11: 12 | N11: 13 | O11: 14
A12: 1 | B12: Lemari Kayu | D12: Lokal / Hand Made | G12: Kayu/ Playwood | H12: 2020 | I12: 02.06.02.01.001 | J12: 0001 | K12: 84403000 | L12: Baik
A13: =A12+1 -> 2 | B13: AC Unit | D13: Daikin / FTNE25JEV14 | G13: Besi Plastik | H13: 2016 1 PK | I13: 02.06.02.04.003 | J13: 0012 | K13: =5000000/2 -> 2500000 | L13: Baik
A14: =A13+1 -> 3 | B14: AC Unit | D14: Daikin / FTV25CXV | H14: 2020 | I14: 02.06.02.04.003 | J14: 0016 | K14: =32663710/4 -> 8165927.5 | L14: Baik
A15: =A14+1 -> 4 | B15: Televisi | D15: Samsung./ 43n5001 | H15: 2020 | I15: 02.06.02.06.003 | J15: 0007 | K15: =16532240/3 -> 5510746.7 | L15: Baik
A16: =A15+1 -> 5 | B16: Sound System | D16: Soundqueen/ SK210 | H16: 2020 | I16: 02.06.02.06.008 | J16: 0002 s/d 0003 | K16: 7013680 | L16: Baik
A17: =A16+1 -> 6 | B17: Meja Rapat Pejabat Lain-Lain | D17: GALANT / - | H17: 2020 | I17: 02.06.04.02.14 | J17: 0001 | K17: 4125800 | L17: Baik
A18: =A17+1 -> 7 | B18: Kursi Rapat | D18: Indachi / D 910 | G18: Besi dan Plastik | H18: 2014 | I18: 02.06.02.01.027 | J18: 0010 | K18: 743915 | L18: Baik
A19: =A18+1 -> 8 | B19: Kursi Rapat | D19: Indachi / D 910 | G19: Besi dan Plastik | H19: 2014 | I19: 02.06.02.01.027 | J19: 0012 | K19: 743915 | L19: Baik
A20: =A19+1 -> 9 | B20: Kursi Rapat | D20: Indachi / D 910 | G20: Besi dan Plastik | H20: 2014 | I20: 02.06.02.01.027 | K20: 743915 | L20: Baik
A21: =A20+1 -> 10 | B21: Kursi Putar | D21: USHUTO / Kursi Kerja 6033 | G21: Besi Plastik | H21: 2013 | I21: 02.06.02.01.030 | J21: 0026 | K21: 486971.68 | L21: Baik
A22: =A21+1 -> 11 | B22: Kursi Putar | D22: Indachi / D 920 | G22: Besi Plastik | H22: 2014 | I22: 02.06.02.01.030 | J22: 0034 | K22: 794179 | L22: Baik
A23: =A22+1 -> 12 | B23: Kursi Putar | D23: Indachi / D 920 | G23: Besi Plastik | H23: 2014 | I23: 02.06.02.01.030 | J23: 0039 | K23: 794179 | L23: Baik
A24: =A23+1 -> 13 | B24: Kursi Putar | D24: Indachi / D 920 | G24: Besi Plastik | H24: 2014 | I24: 02.06.02.01.030 | J24: 0040 | K24: 794179 | L24: Baik
A25: =A24+1 -> 14 | B25: Kursi Putar | D25: Indachi / D 920 | G25: Besi Plastik | H25: 2014 | I25: 02.06.02.01.030 | J25: 0043 | K25: 794179 | L25: Baik
A26: =A25+1 -> 15 | B26: Kursi Putar | D26: Indachi / D 920 | G26: Besi Plastik | H26: 2014 | I26: 02.06.02.01.030 | J26: 0044 | K26: 794179 | L26: Baik | O26: barang sudah dipindahkan
A27: =A26+1 -> 16 | B27: Kursi Putar | D27: Indachi / D 920 | G27: Besi Plastik | H27: 2014 | I27: 02.06.02.01.030 | K27: 794179 | L27: Baik
A28: =A27+1 -> 17 | B28: Kursi Kerja Pejabat Eselon IV | D28: Tiger T98 AH / Esselon IV | G28: Besi Plastik | H28: 2011 | I28: 02.06.04.03.006 | J28: 0004 | K28: 1755000 | L28: Baik
A29: =A28+1 -> 18 | B29: Kursi Kerja Pejabat Eselon IV | D29: BROTHER BG 510 An / Kursi Kerja | G29: Kayu Partikel | H29: 2017 | I29: 02.06.04.03.006 | J29: 0009 | K29: 1066031 | L29: Baik
A30: =A29+1 -> 19 | B30: Kursi Rapat Pejabat Lain-lain | D30: Matrix KSS-01 /- | H30: 2020 | I30: 02.06.04.04.008 | J30: 0001 s/d 0030 | K30: 9468480 | L30: Baik
A31: =A30+1 -> 20 | B31: Proyektor + Attachment | D31: INFOCUS / INI24STX | G31: Besi Plastik | H31: 2019 | I31: 02.07.01.01.003 | J31: 0002 | K31: 15090000 | L31: Baik | O31: barang dipinjam bidang
A32: 21 | B32: Filling kabinet | D32: BROTHER | G32: Besi | H32: 2014 | I32: 02.06.01.04.004 | J32: 0013 | L32: Baik
C33: Mengetahui : | L33: Banjarmasin, Dersember 2025
C35: Kepala Bakesbangpol Kota Banjarmasin, | L35: Pengurus Barang
C39: Dr. H. LUKMAN FADLUN, SH, MH | L39: TRISNAWATI M ULYO HAPSARI, SE
C40: Pembina Utama Muda | L40: ='RUANG KASUBBAG KEUANGAN'!L30 -> NIP. 19721124 200604 2 005
C41: NIP. 19691013 200003 1 004

Sheet RUANG PELAYANAN
G1: KARTU INVENTARIS RUANGAN | N1: MODEL INV. 6
A3: Kab/Kota | C3: Kota Banjarmasin
A4: Propinsi | C4: Kalimantan Selatan
A5: Satuan Kerja | C5: Badan Kesatuan Bangsa dan Politik Kota Banjarmasin
A6: Ruangan | C6: PELAYANAN
A8: NO.KODE LOKASI :
A9: No. | B9: Nama Barang | D9: Merk/ | E9: No. Seri | H9: Tahun | I9: No. Kode Barang | J9: Jumlah | K9: Harga | L9: Keadaan Barang | O9: Keterangan
A10: Urut | B10: Jenis Barang | D10: Model | E10: Pabrik | F10: Ukuran | G10: Bahan | H10: Pembuatan | J10: Barang | K10: Beli/ | L10: Baik | M10: Kurang Baik | N10: Rusak Berat | O10: Mutasi dll
H11: Atau Pembelian | J11: Register x) | K11: Perolehan | L11: (B) | M11: (KB) | N11: (RB)
A12: 1 | B12: 2 | D12: 3 | E12: 4 | F12: 5 | G12: 6 | H12: 7 | I12: 8 | J12: 9 | K12: 10 | L12: 11 | M12: 12 | N12: 13 | O12: 14
A13: 1 | B13: Kursi Besi / Metal | D13: -/Warna Cream | G13: Besi | H13: 1997 | I13: 02.06.02.01.005 | J13: 0002 | K13: 148648.5 | L13: Baik
A14: =A13+1 -> 2 | B14: Meja Panjang | D14: Lokal / Handmade | G14: Kayu | H14: 2020 | I14: 02.06.02.01.009 | J14: 0001 | K14: 5860000 | L14: Baik
A15: =A14+1 -> 3 | B15: Meja Reception | D15: Lokal / Handmade | G15: Kayu / Plywood | H15: 2020 | I15: 02.06.02.01.017 | J15: 0001 | K15: 24337500 | L15: Baik
A16: =A15+1 -> 4 | B16: Kursi Tamu | D16: Lokal / Handmade | G16: Kayu | H16: 2020 | I16: 02.06.02.01.019 | J16: 0003 | K16: 15628800 | L16: Baik
A17: =A16+1 -> 5 | B17: Kursi rapat | D17: Indachi / D910 | G17: Besi dan Plastik | H17: 2014 | I17: 02.06.02.01.027 | J17: 0011 | K17: 743915 | L17: Baik | O17: Barang sudah dipindahkan
A18: =A17+1 -> 6 | B18: Kursi Putar | D18: Indachi / D920 | G18: Besi Plastik | H18: 2014 | I18: 02.06.02.01.030 | J18: 0037 | K18: 794180 | L18: Baik
A19: =A18+1 -> 7 | B19: AC Unit | D19: Daikin / FTV25CXV | H19: 2020 | I19: 02.06.02.04.003 | J19: 0017 | K19: 8165927.5 | L19: Baik
A20: =A19+1 -> 8 | B20: Televisi | D20: Samsung./ 43n5001 | H20: 2020 | I20: 02.06.02.06.003 | J20: 0006 | K20: 5510746.7 | L20: Baik
A21: =A20+1 -> 9 | B21: Dispenser | D21: Toshiba / RWFW1830 | H21: 2020 | I21: 02.06.02.06.039 | J21: 0003 | K21: 4458695 | L21: Baik
A22: =A21+1 -> 10 | B22: PC Unit | D22: Lenovo / C260 | G22: Besi Plastik | H22: 2017 | I22: 02.06.03.02.001 | J22: 0016 | K22: 6976243 | L22: Baik
A23: =A22+1 -> 11 | B23: Printer | D23: EPSON / L120 | H23: ;2017 | I23: 02.06.03.05.003 | J23: 0026 | K23: 2173757 | L23: Baik
C26: Mengetahui : | K26: Banjarmasin, 1 Juli 2021
C28: Kepala Bakesbangpol Kota Banjarmasin, | L28: Pengurus Barang
C32: Dr. H. LUKMAN FADLUN, SH, MH | L32: TRISNAWATI M ULYO HAPSARI, SE
C33: Pembina Utama Muda | L33: ='RUANG KASUBBAG SUNRAM'!L28 -> NIP. 19721124 200604 2 005
C34: NIP. 19691013 200003 1 004

Sheet RUANG DAPUR
G1: KARTU INVENTARIS RUANGAN | N1: MODEL INV. 6
A3: Kab/Kota | C3: Kota Banjarmasin
A4: Propinsi | C4: Kalimantan Selatan
A5: Satuan Kerja | C5: Badan Kesatuan Bangsa dan Politik Kota Banjarmasin
A6: Ruangan | C6: DAPUR
A8: NO.KODE LOKASI :
A9: No. | B9: Nama Barang | D9: Merk/ | E9: No. Seri | F9: Ukuran | G9: Bahan | H9: Tahun | J9: Jumlah | K9: Harga | L9: Keadaan Barang | O9: Keterangan
A10: Urut | B10: Jenis Barang | D10: Model | E10: Pabrik | H10: Pembuatan | I10: No. Kode Barang | J10: Barang | K10: Beli/ | L10: Baik | M10: Kurang Baik | N10: Rusak Berat | O10: Mutasi dll
H11: Atau Pembelian | J11: Register x) | K11: Perolehan | L11: (B) | M11: (KB) | N11: (RB)
A12: 1 | B12: 2 | D12: 3 | E12: 4 | F12: 5 | G12: 6 | H12: 7 | I12: 8 | J12: 9 | K12: 10 | L12: 11 | M12: 12 | N12: 13 | O12: 14
A13: 1 | B13: Lemari Kayu | D13: Lokal / Hand Made | G13: Kayu/ Playwood | H13: 2020 | I13: 02.06.02.01.001 | J13: 0002 | K13: 3959900 | L13: Baik
A14: =A13+1 -> 2 | B14: Lemari ES | D14: LG / GR602JLC | G14: Besi | H14: 2011 | I14: 02.06.02.04.001 | J14: 0003 | K14: 14700000 | L14: Baik
A15: =A14+1 -> 3 | B15: Meja Komputer | D15: Indachi | G15: Kayu | H15: 2013 | I15: 02.06.03.01.037 | J15: 0001 | L15: Baik
A16: =A15+1 -> 4 | B16: Lemari Kayu | D16: Buatan Lokal / - | G16: Kayu Kaca | H16: 2000 | I16: 02.06.01.04.014 | J16: 0012 | K16: 350000 | L16: Baik | M16: Kurang Baik | O16: Usul Penghapusan
A17: =A16+1 -> 5 | B17: Kursi Besi / Metal | D17: - / Warna Cream | G17: Basi | H17: 1997 | I17: 02.06.02.01.005 | J17: 0001 | K17: 148648.5 | M17: Kurang Baik | O17: Usul Penghapusan
A18: =A17+1 -> 6 | B18: Kursi Besi / Metal | D18: - / Warna Cream | G18: Basi | H18: 1997 | I18: 02.06.02.01.005 | J18: 0009 | K18: 148648.5 | M18: Kurang Baik | O18: Usul Penghapusan
A19: =A18+1 -> 7 | B19: Kursi Besi / Metal | D19: - / Warna Cream | G19: Basi | H19: 1997 | I19: 02.06.02.01.005 | J19: 0012 | K19: 148648.5 | M19: Kurang Baik | O19: Usul Penghapusan
A20: =A19+1 -> 8 | B20: Kursi Besi / Metal | D20: - / Warna Cream | G20: Basi | H20: 1997 | I20: 02.06.02.01.005 | J20: 0015 | K20: 148648.5 | M20: Kurang Baik | O20: Usul Penghapusan
A21: =A20+1 -> 9 | B21: Kursi Besi / Metal | D21: - / Warna Cream | G21: Basi | H21: 1997 | I21: 02.06.02.01.005 | K21: 148648.5 | M21: Kurang Baik | O21: Usul Penghapusan
A22: =A21+1 -> 10 | B22: Kursi Rapat | D22: Indachi / D 910 | G22: Besi dan Plastik | H22: 2014 | I22: 02.06.02.01.027 | J22: 0009 | K22: 743915 | L22: Baik | M22: Kurang Baik | O22: Usul Penghapusan
A23: =A22+1 -> 11 | B23: Kursi Putar | D23: USHUTO / Kursi Kerja 6033 | G23: Besi Plastik | H23: 2013 | I23: 02.06.02.01.030 | J23: 0024 | K23: 486971.68 | L23: Baik | M23: Kurang Baik | O23: Usul Penghapusan
A24: =A23+1 -> 12 | B24: Kursi Putar | D24: Indhaci / D 920 | G24: Besi Plastik | H24: 2014 | I24: 02.06.02.01.030 | J24: 0035 | K24: 794180 | L24: Baik | M24: Kurang Baik | O24: Usul Penghapusan
C26: Mengetahui : | L26: Banjarmasin, Desember 2025
C27: Kepala Bakesbangpol Kota Banjarmasin, | L27: Pengurus Barang,
C31: Dr. H. LUKMAN FADLUN, SH, MH | L31: TRISNAWATI M ULYO HAPSARI, SE
C32: Pembina Utama Muda | L32: ='RUANG PELAYANAN'!L33 -> NIP. 19721124 200604 2 005
C33: NIP. 19691013 200003 1 004

Sheet RUANG KABID IDEOLOGI
G1: KARTU INVENTARIS RUANGAN | N1: MODEL INV. 6
A3: Kab/Kota | C3: Kota Banjarmasin
A4: Propinsi | C4: Kalimantan Selatan
A5: Satuan Kerja | C5: Badan Kesatuan Bangsa dan Politik Kota Banjarmasin
A6: Ruangan | C6: Kabid Ideologi dan Wawasan Kebangsaan
A8: NO.KODE LOKASI :
A9: No. | B9: Nama Barang | D9: Merk/ | E9: No. Seri | F9: Ukuran | G9: Bahan | H9: Tahun | J9: Jumlah | K9: Harga | L9: Keadaan Barang | O9: Keterangan
A10: Urut | B10: Jenis Barang | D10: Model | E10: Pabrik | H10: Pembuatan | I10: No. Kode Barang | J10: Barang | K10: Beli/ | L10: Baik | M10: Kurang Baik | N10: Rusak Berat | O10: Mutasi dll
H11: Atau Pembelian | J11: Register x) | K11: Perolehan | L11: (B) | M11: (KB) | N11: (RB)
A12: 1 | B12: 2 | D12: 3 | E12: 4 | F12: 5 | G12: 6 | H12: 7 | I12: 8 | J12: 9 | K12: 10 | L12: 11 | M12: 12 | N12: 13 | O12: 14
A13: 1 | B13: Lemari Besi | D13: Brother / - | G13: Besi | H13: 2008 | I13: 02.06.01.04.001 | J13: 0007 | K13: 1730000 | L13: Baik
A14: =A13+1 -> 2 | B14: Kursi Besi / Metal | D14: - / Warna Crean | G14: Besi | H14: 1997 | I14: 02.06.02.01.005 | J14: 0005 | K14: 148648.50 | L14: Baik | O14: barang sudah pindah
A15: =A14+1 -> 3 | B15: Kursi Besi / Metal | D15: - / Warna Crean | G15: Besi | H15: 1997 | I15: 02.06.02.01.005 | J15: 0013 | K15: 148648.50 | L15: Baik | O15: barang sudah pindah
A16: =A15+1 -> 4 | B16: PC Unit | D16: LENOVO / AIO 330 (A6) | G16: Campuran | H16: 2020 | I16: 02.06.03.02.001 | J16: 0022 | K16: 6996010 | L16: Baik | O16: Barang di pinjamkan ke staf
A17: =A16+1 -> 5 | B17: Printer | D17: EPSON /L360 | H17: 2018 | I17: 02.06.03.05.003 | J17: 0028 | K17: 2428691 | L17: Baik | O17: Barang di pinjamkan ke staf
A18: =A17+1 -> 6 | B18: Meja Kerja Pejabat Eselon III | D18: ZETTA / MT2015 | H18: 2018 | I18: 02.06.04.01.005 | J18: 0007 | K18: 3433301 | L18: Baik
A19: =A18+1 -> 7 | B19: Meja Kerja Pejabat Eselon IV | D19: Active / Meja Kerja Staf | G19: Kayu Partikel | H19: 2008 | I19: 02.06.04.01.006 | J19: 0030 | K19: 562500 | L19: Baik | O19: usulan penghapusan
A20: =A19+1 -> 8 | B20: Kursi Kerja Pejabat Eselon III | G20: Besi Plastik | H20: 1997 | I20: 02.06.04.03.005 | J20: 0011 | K20: 539000 | L20: Baik
A21: 9 | B21: Filing Kabinet | D21: Brother / - | G21: Besi | H21: 2006 | I21: 02.06.01.04.004 | J21: 0001 | L21: Baik
C24: Mengetahui : | L24: Banjarmasin, Desember 2025
C25: Kepala Bakesbangpol Kota Banjarmasin, | L25: Pengurus Barang,
C29: Dr. H. LUKMAN FADLUN, SH, MH | L29: TRISNAWATI M ULYO HAPSARI, SE
C30: Pembina Utama Muda | L30: ='RUANG DAPUR'!L32 -> NIP. 19721124 200604 2 005
C31: NIP. 19691013 200003 1 004

Sheet Sheet1

Sheet RUANG KABID HANSENIBUD
G1: KARTU INVENTARIS RUANGAN | N1: MODEL INV. 6
A3: Kab/Kota | C3: Kota Banjarmasin
A4: Propinsi | C4: Kalimantan Selatan
A5: Satuan Kerja | C5: Badan Kesatuan Bangsa dan Politik Kota Banjarmasin
A6: Ruangan | C6: Kabid Ketahanan Seni, Budaya, Agama, Kemasyarakatan dan Ekonomi
A8: NO.KODE LOKASI :
A9: No. | B9: Nama Barang | D9: Merk/ | E9: No. Seri | F9: Ukuran | G9: Bahan | H9: Tahun | J9: Jumlah | K9: Harga | L9: Keadaan Barang | O9: Keterangan
A10: Urut | B10: Jenis Barang | D10: Model | E10: Pabrik | H10: Pembuatan | I10: No. Kode Barang | J10: Barang | K10: Beli/ | L10: Baik | M10: Kurang Baik | N10: Rusak Berat | O10: Mutasi dll
H11: Atau Pembelian | J11: Register x) | K11: Perolehan | L11: (B) | M11: (KB) | N11: (RB)
A12: 1 | B12: 2 | D12: 3 | E12: 4 | F12: 5 | G12: 6 | H12: 7 | I12: 8 | J12: 9 | K12: 10 | L12: 11 | M12: 12 | N12: 13 | O12: 14
A13: 1 | B13: Lemari Besi | D13: Brother / B 203 | G13: Besi | H13: 2014 | I13: 02.06.01.04.001 | J13: 0017 | K13: 3669674 | L13: Baik
A14: =A13+1 -> 2 | B14: Filling Besi / Metal | D14: BROTHER / BS - 102 | G14: Besi | H14: 2014 | I14: 02.06.01.04.004 | J14: 0014 | K14: 3292652 | L14: Baik
A15: =A14+1 -> 3 | B15: Kursi Lipat | D15: MATRIX / - | H15: 2018 | I15: 02.06.02.01.034 | J15: 0005 | K15: 333232 | L15: Baik | O15: Barang sudah dipindahkan
A16: =A15+1 -> 4 | B16: AC Unit | D16: Samsung / AS09TSMNXEA | G16: Besi Plastik | H16: 2013 | I16: 02.06.02.04.003 | J16: 0007 | K16: 4150000 | L16: Baik | O16: Barang Baru
A17: =A16+1 -> 5 | B17: Kursi Putar | D17: Isabel 325 T / - | G17: Besi Plastik | H17: 2010 | I17: 02.06.02.01.030 | J17: 0021 | K17: 320000 | L17: Baik
A18: =A17+1 -> 6 | B18: PC Unit | D18: Lenovo / C260 | G18: Besi Plastik | H18: 2015 | I18: 02.06.03.02.001 | J18: 0015 | K18: 6026316 | L18: Baik | O18: barang dipinjamkan ke staf
A19: =A18+1 -> 7 | B19: Printer | D19: EPSON /L360 | G19: Besi Plastik | H19: 2016 | I19: 02.06.03.05.003 | J19: 0023 | K19: 3142612 | L19: Baik
A20: =A19+1 -> 8 | B20: Meja Kerja Pejabat Eselon III | D20: ZETTA / MT201S / Esselon III | G20: Kayu Pertikel | H20: 2014 | I20: 02.06.04.01.005 | J20: 0003 | K20: 5126984 | L20: Baik
A21: =A20+1 -> 9 | B21: Kursi Kerja Pejabat Eselon IV | D21: Indachi D 800 / Esselon IV | G21: Besi Plastik | H21: 2010 | I21: 02.06.04.03.006 | J21: 0006 | K21: 942500 | L21: Baik
A22: 10 | B22: Kursi Rapat | D22: MATRIX / - | G22: Besi | H22: 2020 | I22: 02.06.04.04.008 | J22: 0001 | K22: 315616 | L22: Baik
A23: 10 | B23: Kursi Rapat | D23: MATRIX / - | G23: Besi | H23: 2020 | I23: 02.06.04.04.008 | J23: 0026 | K23: 315616 | L23: Baik
A24: 11 | B24: Laptop
C26: Mengetahui : | L26: Banjarmasin, Desember 2025
C27: Kepala Bakesbangpol Kota Banjarmasin, | L27: Pengurus Barang,
C31: Dr. H. LUKMAN FADLUN, SH, MH | L31: TRISNAWATI M ULYO HAPSARI, SE
C32: Pembina Utama Muda | L32: ='RUANG KABID IDEOLOGI'!L30 -> NIP. 19721124 200604 2 005
C33: NIP. 19691013 200003 1 004

Sheet RUANG KABID POLITIK
G1: KARTU INVENTARIS RUANGAN | N1: MODEL INV. 6
A3: Kab/Kota | C3: Kota Banjarmasin
A4: Propinsi | C4: Kalimantan Selatan
A5: Satuan Kerja | C5: Badan Kesatuan Bangsa dan Politik Kota Banjarmasin
A6: Ruangan | C6: Kabid Politik
A8: NO.KODE LOKASI :
A9: No. | B9: Nama Barang | D9: Merk/ | E9: No. Seri | F9: Ukuran | G9: Bahan | H9: Tahun | J9: Jumlah | K9: Harga | L9: Keadaan Barang | O9: Keterangan
A10: Urut | B10: Jenis Barang | D10: Model | E10: Pabrik | H10: Pembuatan | I10: No. Kode Barang | J10: Barang | K10: Beli/ | L10: Baik | M10: Kurang Baik | N10: Rusak Berat | O10: Mutasi dll
H11: Atau Pembelian | J11: Register x) | K11: Perolehan | L11: (B) | M11: (KB) | N11: (RB)
A12: 1 | B12: 2 | D12: 3 | E12: 4 | F12: 5 | G12: 6 | H12: 7 | I12: 8 | J12: 9 | K12: 10 | L12: 11 | M12: 12 | N12: 13 | O12: 14
A13: 1 | B13: Lemari Besi | D13: KRISBROW / KW17-195 | G13: Besi | H13: 2012 | I13: 02.06.01.04.001 | J13: 0012 | K13: 3400000 | L13: Baik
A14: =A13+1 -> 2 | B14: Filling Besi / Metal | D14: BROTHER / BS - 102 | G14: Besi | H14: 2014 | I14: 02.06.01.04.004 | J14: 0012 | K14: 3292653 | L14: Baik
A15: =A14+1 -> 3 | B15: Kursi Besi/Metal | D15: - / Warna Cream | G15: Besi | H15: 1997 | I15: 02.06.02.01.005 | J15: 0003 | K15: 148648.50 | M15: Kurang Baik
A16: =A15+1 -> 4 | B16: Kursi Besi/Metal | D16: - / Warna Cream | G16: Besi | H16: 1997 | I16: 02.06.02.01.005 | J16: 0006 | K16: 148648.50 | M16: Kurang Baik
A17: =A16+1 -> 5 | B17: Meja Komputer | D17: AZTEC / CD 800 P | G17: Serbuk Kayu | H17: 2013 | I17: 02.06.02.01.037 | J17: 0002 | K17: 588424.11 | L17: Baik
A18: =A17+1 -> 6 | B18: Meja Kerja Pejabat Eselon III | D18: ZETTA / MT 201 / Esselon III | G18: Kayu Pertikel | H18: 2017 | I18: 02.06.04.01.005 | J18: 0005 | K18: 2284351 | L18: Baik
A19: =A18+1 -> 7 | B19: Kursi Kerja Pejabat Eselon IV | D19: Indachi D 821 CR/ Kursi Kerja Staf | G19: Kayu Pertikel | H19: 2015 | I19: 02.06.04.03.006 | J19: 0007 | K19: 2181159 | L19: Baik
C22: Mengetahui : | L22: Banjarmasin, Desember 2025
C23: Kepala Bakesbangpol Kota Banjarmasin, | L23: Pengurus Barang,
C27: Dr. H. LUKMAN FADLUN, SH, MH | L27: TRISNAWATI M ULYO HAPSARI, SE
C28: Pembina Utama Muda | L28: ='RUANG KABID HANSENIBUD'!L32 -> NIP. 19721124 200604 2 005
C29: NIP. 19691013 200003 1 004

Sheet RUANG KABID WASNAS
G1: KARTU INVENTARIS RUANGAN | N1: MODEL INV. 6
A3: Kab/Kota | C3: Kota Banjarmasin
A4: Propinsi | C4: Kalimantan Selatan
A5: Satuan Kerja | C5: Badan Kesatuan Bangsa dan Politik Kota Banjarmasin
A6: Ruangan | C6: Kabid Kewaspadaan Nasional
A8: NO.KODE LOKASI :
A9: No. | B9: Nama Barang | D9: Merk/ | E9: No. Seri | F9: Ukuran | G9: Bahan | H9: Tahun | J9: Jumlah | K9: Harga | L9: Keadaan Barang | O9: Keterangan
A10: Urut | B10: Jenis Barang | D10: Model | E10: Pabrik | H10: Pembuatan | I10: No. Kode Barang | J10: Barang | K10: Beli/ | L10: Baik | M10: Kurang Baik | N10: Rusak Berat | O10: Mutasi dll
H11: Atau Pembelian | J11: Register x) | K11: Perolehan | L11: (B) | M11: (KB) | N11: (RB)
A12: 1 | B12: 2 | D12: 3 | E12: 4 | F12: 5 | G12: 6 | H12: 7 | I12: 8 | J12: 9 | K12: 10 | L12: 11 | M12: 12 | N12: 13 | O12: 14
A13: 1 | B13: Lemari Besi | D13: LION / L 33 Swing Door | G13: Besi | H13: 2013 | I13: 02.06.01.04.001 | J13: 0013 | K13: 2820699 | L13: Baik
A14: =A13+1 -> 2 | B14: Filling Besi / Metal | D14: BROTHER / B - 104 | G14: Besi | H14: 2017 | I14: 02.06.01.04.004 | J14: 0015 | K14: 2081257 | L14: Baik
A15: =A14+1 -> 3 | B15: Filling Besi / Metal | D15: BROTHER / B - 104 | H15: 2018 | I15: 02.06.01.04.004 | J15: 0017 | K15: 2095323 | L15: Baik
A16: =A15+1 -> 4 | B16: Kursi Besi / Metal | D16: - / Warna Cream | G16: Basi | H16: 1997 | I16: 02.06.02.01.005 | J16: 0008 | K16: 148648.5 | M16: Kurang Baik
A17: =A16+1 -> 5 | B17: AC Unit | D17: Daikin/FTV25CXV | H17: 2020 | I17: 02.06.02.04.003 | J17: 0018 | K17: 8165750 | L17: Baik
A18: =A17+1 -> 6 | B18: Meja Kerja Pejabat Eselon III | D18: ZETTA / MT-301 / Esselon III | G18: Kayu Pertikel | H18: 2015 | I18: 02.06.04.01.005 | J18: 0004 | K18: 3600000 | L18: Baik
A19: =A18+1 -> 7 | B19: Kursi Kerja Pejabat Eselon III | D19: INDACHI/ 741 CR | G19: Besi Plastik | H19: 2018 | I19: 02.06.04.03.005 | J19: 0015 | K19: 1969099 | L19: Baik
C21: Mengetahui : | L21: Banjarmasin, Desember 2025
C23: Kepala Bakesbangpol Kota Banjarmasin, | L23: Pengurus Barang
C27: Dr. H. LUKMAN FADLUN, SH, MH | L27: TRISNAWATI M ULYO HAPSARI, SE
C28: Pembina Utama Muda | L28: ='RUANG KABID POLITIK'!L28 -> NIP. 19721124 200604 2 005
C29: NIP. 19691013 200003 1 004

Sheet RUANG DEPAN BIDANG KET
H1: KARTU INVENTARIS RUANGAN | O1: MODEL INV. 6
B3: Kab/Kota | D3: Kota Banjarmasin
B4: Propinsi | D4: Kalimantan Selatan
B5: Satuan Kerja | D5: Badan Kesatuan Bangsa dan Politik Kota Banjarmasin
B6: Ruangan | D6: DEPAN BIDANG
B8: NO.KODE LOKASI :
B9: No. | C9: Nama Barang | E9: Merk/ | F9: No. Seri | G9: Ukuran | H9: Bahan | I9: Tahun | K9: Jumlah | L9: Harga | M9: Keadaan Barang | P9: Keterangan
B10: Urut | C10: Jenis Barang | E10: Model | F10: Pabrik | I10: Pembuatan | J10: No/. Kode Barang | K10: Barang | L10: Beli/ | M10: Baik | N10: Kurang Baik | O10: Rusak Berat | P10: Mutasi dll
I11: Atau Pembelian | K11: Register x) | L11: Perolehan | M11: (B) | N11: (KB) | O11: (RB)
B12: 1 | C12: 2 | E12: 3 | F12: 4 | G12: 5 | H12: 6 | I12: 7 | J12: 8 | K12: 9 | L12: 10 | M12: 11 | N12: 12 | O12: 13 | P12: 14
B13: 1 | C13: Filling Besi / Metal | E13: BROTHER / - | H13: Besi | I13: 2006 | J13: 02.06.01.04.004 | K13: 0001 | L13: 1220000 | M13: Baik
B14: =B13+1 -> 2 | C14: Filling Besi / Metal | E14: BROTHER / - | H14: Besi | I14: 2006 | J14: 02.06.01.04.004 | K14: 0006 | L14: 1220000 | M14: Baik
B15: =B14+1 -> 3 | C15: Kursi Besi/Metal | E15: - / Warna Cream | H15: Besi | I15: 1997 | J15: 02.06.02.01.005 | K15: 0002 | L15: 148648.50 | M15: Baik | P15: Tidak ada padanKIB
B16: =B15+1 -> 4 | C16: Kursi Rapat | E16: Chitose / Warna Biru | H16: Besi | I16: 2009 | J16: 02.06.02.01.027 | K16: 0001 | L16: 350000 | M16: Baik
B17: =B16+1 -> 5 | C17: Kursi Rapat | E17: Indachi / D 910 | H17: Besi dan Plastik | I17: 2014 | J17: 02.06.02.01.027 | K17: 0013 | L17: 743915 | M17: Baik
B18: =B17+1 -> 6 | C18: Kursi Rapat | E18: Indachi / D 910 | H18: Besi dan Plastik | I18: 2014 | J18: 02.06.02.01.027 | K18: 0014 | L18: 743917 | M18: Baik
B19: =B18+1 -> 7 | C19: Kursi Putar | E19: USHUTO/ Kursi Kerja 6033 | H19: Besi Plastik | I19: 2013 | J19: 02.06.02.01.030 | K19: 0028 | L19: 486971.68 | M19: Baik
B20: =B19+1 -> 8 | C20: Kursi Putar | E20: Indachi / D 920 | H20: Besi Plastik | I20: 2014 | J20: 02.06.02.01.030 | K20: 0030 | L20: 794180 | M20: Baik
B21: =B20+1 -> 9 | C21: Kursi Putar | E21: Indachi / D 920 | H21: Besi Plastik | I21: 2014 | J21: 02.06.02.01.030 | K21: 0042 | L21: 794180 | M21: Baik
B22: =B21+1 -> 10 | C22: Kursi Putar | E22: Indachi / D 920 | H22: Besi Plastik | I22: 2014 | K22: 0046 | L22: 794180 | M22: Baik
B23: =B22+1 -> 11 | C23: Kursi Lipat | E23: MATRIX / - | I23: 2018 | J23: 02.06.02.01.034 | K23: 0004 | L23: 333232 | M23: Baik
B24: =B23+1 -> 12 | C24: Kursi Lipat | E24: MATRIX / - | I24: 2018 | J24: 02.06.02.01.034 | K24: 0006 | L24: 333232 | M24: Baik
B25: =B24+1 -> 13 | C25: Kursi Lipat | E25: MATRIX / - | I25: 2018 | J25: 02.06.02.01.034 | K25: 0009 | L25: 333232 | M25: Baik
B26: =B25+1 -> 14 | C26: PC Unit | E26: Intel - Casing ATX-LG/MB MSI G41M-P28- LG wide 16 | H26: Besi Plastik | I26: 2012 6 inci | J26: 02.06.03.02.001 | K26: 0010 | L26: 3980000 | M26: Baik
B27: =B26+1 -> 15 | C27: PC Unit | E27: Intel - Casing DE Case-LG / Pentium ® G 2020Asrock HGI-LG LED 16 | H27: Besi Plastik | I27: 2013 | J27: 02.06.03.02.001 | K27: 0012 | L27: 3922641.5 | M27: Baik
B36: No. | C36: Nama Barang | E36: Merk/ | F36: No. Seri | G36: Ukuran | H36: Bahan | I36: Tahun | K36: Jumlah | L36: Harga | M36: Keadaan Barang | P36: Keterangan
B37: Urut | C37: Jenis Barang | E37: Model | F37: Pabrik | I37: Pembuatan | J37: No/. Kode Barang | K37: Barang | L37: Beli/ | M37: Baik | N37: Kurang Baik | O37: Rusak Berat | P37: Mutasi dll
I38: Atau Pembelian | K38: Register x) | L38: Perolehan | M38: (B) | N38: (KB) | O38: (RB)
B39: 1 | C39: 2 | E39: 3 | F39: 4 | G39: 5 | H39: 6 | I39: 7 | J39: 8 | K39: 9 | L39: 10 | M39: 11 | N39: 12 | O39: 13 | P39: 14
B40: =B27+1 -> 16 | C40: PC Unit | E40: Lenovo / C260 | H40: Besi Plastik | I40: 2015 | J40: 02.06.03.02.001 | K40: 0014 | L40: 6026316 | M40: Baik
B41: =B40+1 -> 17 | C41: Printer | E41: EPSON / L 360 | H41: Besi Plastik | I41: 2016 | J41: 02.06.03.05.003 | K41: 0020 | L41: 3142612 | M41: Baik
B42: =B41+1 -> 18 | C42: Printer | E42: EPSON / L 360 | H42: Besi Plastik | I42: 2016 | J42: 02.06.03.05.003 | K42: 0022 | L42: 3142612 | M42: Baik
B43: =B42+1 -> 19 | C43: Printer | E43: EPSON /L120 | H43: Besi Plastik | I43: 2017 | J43: 02.06.03.05.003 | K43: 0027 | L43: 2173757 | M43: Baik
B44: =B43+1 -> 20 | C44: Printer | E44: EPSON /L3110 | H44: Campuran | I44: 2020 | J44: 02.06.03.05.003 | K44: 0034 | L44: =5516570/2 -> 2758285 | M44: Baik | P44: Tidak ada padanKIB
B45: =B44+1 -> 21 | C45: Meja Kerja Pejabat Eselon IV | E45: Blue Shark/ Meja Kerja | H45: Kayu Pertikel | I45: 2008 | J45: 02.06.04.01.006 | K45: 0002 | L45: 372666.67 | M45: Baik | P45: Tidak ada padanKIB
B46: =B45+1 -> 22 | C46: Meja Kerja Pejabat Eselon IV | E46: SAGA OD 022/ Meja Kerja Staf | H46: Kayu Pertikel | I46: 2011 | J46: 02.06.04.01.006 | K46: 0022 | L46: 485000 | M46: Baik | P46: Tidak ada padanKIB
B47: =B46+1 -> 23 | C47: Meja Kerja Pejabat Eselon IV | E47: Solid MTS-2805/ Meja Kerja Staf | H47: Kayu Pertikel | I47: 2010 | J47: 02.06.04.01.006 | K47: 0025 | L47: 485000 | M47: Baik | P47: Tidak ada padanKIB
B48: =B47+1 -> 24 | C48: Meja Kerja Pejabat Eselon IV | E48: General/ Meja Kerja Staf | H48: Kayu Pertikel | I48: 2010 | J48: 02.06.04.01.006 | K48: 0031 | L48: 275000 | M48: Baik | P48: Tidak ada padanKIB
B49: =B48+1 -> 25 | C49: Meja Kerja Pejabat Eselon IV | E49: ZETTA MT201/ Meja Kerja Staf | H49: Kayu Pertikel | I49: 2016 | J49: 02.06.04.01.006 | K49: 0032 | L49: 2282609 | M49: Baik | P49: Tidak ada padanKIB
B50: =B49+1 -> 26 | C50: Meja Kerja Pejabat Eselon IV | E50: ZETTA MT201/ Meja Kerja Staf | H50: Kayu Pertikel | I50: 2016 | J50: 02.06.04.01.006 | K50: 0033 | L50: 2282609 | M50: Baik | P50: Tidak ada padanKIB
...

Sheet RUANG DEPAN BIDANG
G1: KARTU INVENTARIS RUANGAN | N1: MODEL INV. 6
A3: Kab/Kota | C3: Kota Banjarmasin
A4: Propinsi | C4: Kalimantan Selatan
A5: Satuan Kerja | C5: Badan Kesatuan Bangsa dan Politik Kota Banjarmasin
A6: Ruangan | C6: DEPAN BIDANG
A8: NO.KODE LOKASI :
A9: No. | B9: Nama Barang | D9: Merk/ | E9: No. Seri | F9: Ukuran | G9: Bahan | H9: Tahun | J9: Jumlah | K9: Harga | L9: Keadaan Barang | O9: Keterangan
A10: Urut | B10: Jenis Barang | D10: Model | E10: Pabrik | H10: Pembuatan | I10: No/. Kode Barang | J10: Barang | K10: Beli/ | L10: Baik | M10: Kurang Baik | N10: Rusak Berat | O10: Mutasi dll
H11: Atau Pembelian | J11: Register x) | K11: Perolehan | L11: (B) | M11: (KB) | N11: (RB)
A12: 1 | B12: 2 | D12: 3 | E12: 4 | F12: 5 | G12: 6 | H12: 7 | I12: 8 | J12: 9 | K12: 10 | L12: 11 | M12: 12 | N12: 13 | O12: 14
A13: 1 | B13: Filling Besi / Metal | D13: BROTHER / - | G13: Besi | H13: 2006 | I13: 02.06.01.04.004 | J13: 0001 | K13: 1220000 | L13: Baik | O13: Depan Bid Ideologi
A14: =A13+1 -> 2 | B14: Filling Besi / Metal | D14: BROTHER / - | G14: Besi | H14: 2006 | I14: 02.06.01.04.004 | J14: 0006 | K14: 1220000 | L14: Baik | O14: Depan Bid Hansenibud
A15: =A14+1 -> 3 | B15: Kursi Besi/Metal | D15: - / Warna Cream | G15: Besi | H15: 1997 | I15: 02.06.02.01.005 | J15: 0002 | K15: 148648.50 | L15: Baik | O15: Ibu Yani
A16: =A15+1 -> 4 | B16: Kursi Rapat | D16: Chitose / Warna Biru | G16: Besi | H16: 2009 | I16: 02.06.02.01.027 | J16: 0001 | K16: 350000 | L16: Baik | O16: Riyan
A17: =A16+1 -> 5 | B17: Kursi Rapat | D17: Indachi / D 910 | G17: Besi dan Plastik | H17: 2014 | I17: 02.06.02.01.027 | J17: 0013 | K17: 743915 | L17: Baik | O17: Arin
A18: =A17+1 -> 6 | B18: Kursi Rapat | D18: Indachi / D 910 | G18: Besi dan Plastik | H18: 2014 | I18: 02.06.02.01.027 | J18: 0014 | K18: 743917 | L18: Baik | O18: Bu Jannah
A19: =A18+1 -> 7 | B19: Kursi Putar | D19: USHUTO/ Kursi Kerja 6033 | G19: Besi Plastik | H19: 2013 | I19: 02.06.02.01.030 | J19: 0028 | K19: 486971.68 | L19: Baik | O19: Arief
A20: =A19+1 -> 8 | B20: Kursi Putar | D20: Indachi / D 920 | G20: Besi Plastik | H20: 2014 | I20: 02.06.02.01.030 | J20: 0030 | K20: 794180 | L20: Baik | O20: Olip
A21: =A20+1 -> 9 | B21: Kursi Putar | D21: Indachi / D 920 | G21: Besi Plastik | H21: 2014 | I21: 02.06.02.01.030 | J21: 0042 | K21: 794180 | L21: Baik | O21: No Name Depan Wasnas
A22: =A21+1 -> 10 | B22: Kursi Putar | D22: Indachi / D 920 | G22: Besi Plastik | H22: 2014 | J22: 0046 | K22: 794180 | L22: Baik | O22: Adit
A23: =A22+1 -> 11 | B23: Kursi Lipat | D23: MATRIX / - | H23: 2018 | I23: 02.06.02.01.034 | J23: 0004 | K23: 333232 | L23: Baik | O23: Rini
A24: =A23+1 -> 12 | B24: Kursi Lipat | D24: MATRIX / - | H24: 2018 | I24: 02.06.02.01.034 | J24: 0006 | K24: 333232 | L24: Baik | O24: Lutfi
A25: =A24+1 -> 13 | B25: Kursi Lipat | D25: MATRIX / - | H25: 2018 | I25: 02.06.02.01.034 | J25: 0009 | K25: 333232 | L25: Baik | O25: Ibu Sanah
A26: =A25+1 -> 14 | B26: PC Unit | D26: Intel - Casing ATX-LG/MB MSI G41M-P28- LG wide 16 | G26: Besi Plastik | H26: 2012 6 inci | I26: 02.06.03.02.001 | J26: 0010 | K26: 3980000 | L26: Baik | O26: Ibu Jannah
A27: =A26+1 -> 15 | B27: PC Unit | D27: Intel - Casing DE Case-LG / Pentium ® G 2020Asrock HGI-LG LED 16 | G27: Besi Plastik | H27: 2013 | I27: 02.06.03.02.001 | J27: 0012 | K27: 3922641.5 | L27: Baik | O27: Inu Yani
A38: No. | B38: Nama Barang | D38: Merk/ | E38: No. Seri | F38: Ukuran | G38: Bahan | H38: Tahun | J38: Jumlah | K38: Harga | L38: Keadaan Barang | O38: Keterangan
A39: Urut | B39: Jenis Barang | D39: Model | E39: Pabrik | H39: Pembuatan | I39: No/. Kode Barang | J39: Barang | K39: Beli/ | L39: Baik | M39: Kurang Baik | N39: Rusak Berat | O39: Mutasi dll
H40: Atau Pembelian | J40: Register x) | K40: Perolehan | L40: (B) | M40: (KB) | N40: (RB)
A41: 1 | B41: 2 | D41: 3 | E41: 4 | F41: 5 | G41: 6 | H41: 7 | I41: 8 | J41: 9 | K41: 10 | L41: 11 | M41: 12 | N41: 13 | O41: 14
A42: =A27+1 -> 16 | B42: PC Unit | D42: Lenovo / C260 | G42: Besi Plastik | H42: 2015 | I42: 02.06.03.02.001 | J42: 0014 | K42: 6026316 | L42: Baik | O42: Olip
A43: =A42+1 -> 17 | B43: Printer | D43: EPSON / L 360 | G43: Besi Plastik | H43: 2016 | I43: 02.06.03.05.003 | J43: 0020 | K43: 3142612 | L43: Baik | O43: bu Jannah
A44: =A43+1 -> 18 | B44: Printer | D44: EPSON / L 360 | G44: Besi Plastik | H44: 2016 | I44: 02.06.03.05.003 | J44: 0022 | K44: 3142612 | L44: Baik | O44: Olip
A45: =A44+1 -> 19 | B45: Printer | D45: EPSON /L120 | G45: Besi Plastik | H45: 2017 | I45: 02.06.03.05.003 | J45: 0027 | K45: 2173757 | L45: Baik | O45: Adir
A46: =A45+1 -> 20 | B46: Printer | D46: EPSON /L3110 | G46: Campuran | H46: 2020 | I46: 02.06.03.05.003 | J46: 0034 | K46: =5516570/2 -> 2758285 | L46: Baik | O46: Aan
A47: =A46+1 -> 21 | B47: Meja Kerja Pejabat Eselon IV | D47: Blue Shark/ Meja Kerja | G47: Kayu Pertikel | H47: 2008 | I47: 02.06.04.01.006 | J47: 0002 | K47: 372666.67 | L47: Baik | O47: Lutfi
A48: =A47+1 -> 22 | B48: Meja Kerja Pejabat Eselon IV | D48: SAGA OD 022/ Meja Kerja Staf | G48: Kayu Pertikel | H48: 2011 | I48: 02.06.04.01.006 | J48: 0022 | K48: 485000 | L48: Baik | O48: Ibu Sanah
A49: =A48+1 -> 23 | B49: Meja Kerja Pejabat Eselon IV | D49: Solid MTS-2805/ Meja Kerja Staf | G49: Kayu Pertikel | H49: 2010 | I49: 02.06.04.01.006 | J49: 0025 | K49: 485000 | L49: Baik | O49: Arief
A50: =A49+1 -> 24 | B50: Meja Kerja Pejabat Eselon IV | D50: General/ Meja Kerja Staf | G50: Kayu Pertikel | H50: 2010 | I50: 02.06.04.01.006 | J50: 0031 | K50: 275000 | L50: Baik | O50: Arin
A51: =A50+1 -> 25 | B51: Meja Kerja Pejabat Eselon IV | D51: ZETTA MT201/ Meja Kerja Staf | G51: Kayu Pertikel | H51: 2016 | I51: 02.06.04.01.006 | J51: 0032 | K51: 2282609 | L51: Baik | O51: Riyan
A52: =A51+1 -> 26 | B52: Meja Kerja Pejabat Eselon IV | D52: ZETTA MT201/ Meja Kerja Staf | G52: Kayu Pertikel | H52: 2016 | I52: 02.06.04.01.006 | J52: 0033 | K52: 2282609 | L52: Baik | O52: Baitie
...

Sheet RUANG DEPAN BIDANG (2)
G1: KARTU INVENTARIS RUANGAN | N1: MODEL INV. 6
A3: Kab/Kota | C3: Kota Banjarmasin
A4: Propinsi | C4: Kalimantan Selatan
A5: Satuan Kerja | C5: Badan Kesatuan Bangsa dan Politik Kota Banjarmasin
A6: Ruangan | C6: DEPAN BIDANG
A8: NO.KODE LOKASI :
A9: No. | B9: Nama Barang | D9: Merk/ | E9: No. Seri | F9: Ukuran | G9: Bahan | H9: Tahun | J9: Jumlah | K9: Harga | L9: Keadaan Barang | O9: Keterangan
A10: Urut | B10: Jenis Barang | D10: Model | E10: Pabrik | H10: Pembuatan | I10: No/. Kode Barang | J10: Barang | K10: Beli/ | L10: Baik | M10: Kurang Baik | N10: Rusak Berat | O10: Mutasi dll
H11: Atau Pembelian | J11: Register x) | K11: Perolehan | L11: (B) | M11: (KB) | N11: (RB)
A12: 1 | B12: 2 | D12: 3 | E12: 4 | F12: 5 | G12: 6 | H12: 7 | I12: 8 | J12: 9 | K12: 10 | L12: 11 | M12: 12 | N12: 13 | O12: 14
A13: 1 | B13: Filling Besi / Metal | D13: BROTHER / - | G13: Besi | H13: 2006 | I13: 02.06.01.04.004 | J13: 0001 | K13: 1220000 | L13: Baik | O13: Depan Bid Ideologi
A14: =A13+1 -> 2 | B14: Filling Besi / Metal | D14: BROTHER / - | G14: Besi | H14: 2006 | I14: 02.06.01.04.004 | J14: 0006 | K14: 1220000 | L14: Baik | O14: Depan Bid Hansenibud
